File: example_data.csv
[Measurement conditions]
Sample identification,
Comment - 1,"Configuration=Factory configuration, Owner=User-1, Creation date=11/23/2015 10:41:36 AM"
Comment - 2,"Goniometer=HR HD (Theta/2Theta); Minimum step size 2Theta:0.0001; Minimum step size Omega:0.0001"
Comment - 3,"Sample stage=MRD Cradle; Minimum step size Phi:0.01; Minimum step size Chi:0.01; Minimum step size X:0.01; Minimum step size Y:0.01; Minimum step size Z:0.001"
Comment - 4,"Diffractometer system=XPERT-3"
Comment - 5,"Measurement program=C:\PANalytical\Data Collector\Programs\Amanda\rsm change.xrdmp, Identifier={325043B9-92F6-4A52-B686-2113B0982AAC}"
Comment - 6,"Batch program=C:\PANalytical\Data Collector\Programs\Amanda\20amanda719.xrdmp, Identifier={3C923312-5690-4D6B-9821-0F7CD46A6E31}"
Anode material,Cu
K-Alpha1 wavelength,1.5405980
K-Alpha2 wavelength,1.5444260
Ratio K-Alpha2/K-Alpha1,0.500
Divergence slit,Fixed,0.38mm
Receiving slit,0.38
Monochromator used,YES
Generator voltage, 45
Tube current, 40
File date and time,19/Jul/2020 20:22
Unit cell,
h k l, 0 0 0
No. of scans, 401
Measurement step axis,Omega
Measurement step axis range,-0.7858,3.2142,0.0100
Scan axis,2Theta
Scan range,0.68200000,3.69539988,0.0196954
No. of points per scan, 153
Scan type,CONTINUOUS
Phi,0.00
Psi,0.00
X,-1.47
Y,-24.45
Z,7.075
Time per step,116.79
[Scan points]
2Theta position, Omega position, Intensity
0.69184771,-0.7858,2237
1.49936010,-0.7858,45
2.30687248,-0.7858,41
3.11438487,-0.7858,59
0.90849737,-0.7758,851
1.71600976,-0.7758,41
2.52352215,-0.7758,27
3.33103454,-0.7758,82
1.12514704,-0.7658,657
1.93265943,-0.7658,55
2.74017181,-0.7658,80
3.54768420,-0.7658,100
1.34179670,-0.7558,350
2.14930909,-0.7558,37
2.95682148,-0.7558,89
0.75093398,-0.7458,1699
1.55844637,-0.7458,47
2.36595876,-0.7458,26
3.17347114,-0.7458,66
0.96758365,-0.7358,804
1.77509603,-0.7358,43
2.58260842,-0.7358,39
3.39012081,-0.7358,90
1.18423331,-0.7258,628
1.99174570,-0.7258,58
2.79925809,-0.7258,73
3.60677047,-0.7258,86
1.40088298,-0.7158,192
2.20839536,-0.7158,52
3.01590775,-0.7158,67
0.81002025,-0.7058,1078
1.61753264,-0.7058,54
2.42504503,-0.7058,33
3.23255742,-0.7058,79
1.02666992,-0.6958,714
1.83418231,-0.6958,40
2.64169469,-0.6958,36
3.44920708,-0.6958,94
1.24331958,-0.6858,550
2.05083197,-0.6858,39
2.85834436,-0.6858,107
3.66585675,-0.6858,67
1.45996925,-0.6758,88
2.26748164,-0.6758,39
3.07499402,-0.6758,68
0.86910653,-0.6658,931
1.67661891,-0.6658,61
2.48413130,-0.6658,31
3.29164369,-0.6658,74
1.08575619,-0.6558,695
1.89326858,-0.6558,48
2.70078097,-0.6558,50
3.50829335,-0.6558,95
1.30240586,-0.6458,495
2.10991824,-0.6458,31
2.91743063,-0.6458,92
0.71154313,-0.6358,2095
1.51905552,-0.6358,62
2.32656791,-0.6358,36
3.13408030,-0.6358,72
0.92819280,-0.6258,810
1.73570519,-0.6258,48
2.54321757,-0.6258,42
3.35072996,-0.6258,66
1.14484246,-0.6158,666
1.95235485,-0.6158,51
2.75986724,-0.6158,83
3.56737963,-0.6158,83
1.36149213,-0.6058,305
2.16900452,-0.6058,46
2.97651690,-0.6058,88
0.77062941,-0.5958,1400
1.57814179,-0.5958,43
2.38565418,-0.5958,51
3.19316657,-0.5958,53
0.98727907,-0.5858,764
1.79479146,-0.5858,49
2.60230385,-0.5858,46
3.40981623,-0.5858,116
1.20392874,-0.5758,652
2.01144112,-0.5758,49
2.81895351,-0.5758,83
3.62646590,-0.5758,83
1.42057840,-0.5658,161
2.22809079,-0.5658,51
3.03560318,-0.5658,80
0.82971568,-0.5558,941
1.63722807,-0.5558,67
2.44474045,-0.5558,31
3.25225284,-0.5558,79
1.04636534,-0.5458,714
1.85387773,-0.5458,45
2.66139012,-0.5458,46
3.46890251,-0.5458,110
1.26301501,-0.5358,521
2.07052740,-0.5358,53
2.87803978,-0.5358,109
3.68555217,-0.5358,50
1.47966467,-0.5258,65
2.28717706,-0.5258,49
3.09468945,-0.5258,67
0.88880195,-0.5158,876
1.69631434,-0.5158,45
2.50382673,-0.5158,39
3.31133911,-0.5158,70
1.10545162,-0.5058,711
1.91296400,-0.5058,43
2.72047639,-0.5058,55
3.52798878,-0.5058,85
1.32210128,-0.4958,402
2.12961367,-0.4958,54
2.93712605,-0.4958,93
0.73123856,-0.4858,1881
1.53875095,-0.4858,51
2.34626333,-0.4858,35
3.15377572,-0.4858,55
0.94788822,-0.4758,768
1.75540061,-0.4758,50
2.56291300,-0.4758,54
3.37042538,-0.4758,77
1.16453789,-0.4658,642
1.97205028,-0.4658,43
2.77956266,-0.4658,66
3.58707505,-0.4658,66
1.38118755,-0.4558,251
2.18869994,-0.4558,39
2.99621233,-0.4558,85
0.79032483,-0.4458,1228
1.59783722,-0.4458,57
2.40534960,-0.4458,48
3.21286199,-0.4458,53
1.00697450,-0.4358,763
1.81448688,-0.4358,41
2.62199927,-0.4358,45
3.42951166,-0.4358,100
1.22362416,-0.4258,596
2.03113655,-0.4258,61
2.83864893,-0.4258,71
3.64616132,-0.4258,71
1.44027382,-0.4158,131
2.24778621,-0.4158,40
3.05529860,-0.4158,82
0.84941110,-0.4058,900
1.65692349,-0.4058,73
2.46443588,-0.4058,32
3.27194826,-0.4058,73
1.06606077,-0.3958,761
1.87357315,-0.3958,42
2.68108554,-0.3958,49
3.48859793,-0.3958,75
1.28271043,-0.3858,539
2.09022282,-0.3858,40
2.89773521,-0.3858,94
0.69184771,-0.3758,2439
1.49936010,-0.3758,77
2.30687248,-0.3758,54
3.11438487,-0.3758,67
0.90849737,-0.3658,885
1.71600976,-0.3658,64
2.52352215,-0.3658,55
3.33103454,-0.3658,87
1.12514704,-0.3558,667
1.93265943,-0.3558,55
2.74017181,-0.3558,56
3.54768420,-0.3558,90
1.34179670,-0.3458,367
2.14930909,-0.3458,43
2.95682148,-0.3458,94
0.75093398,-0.3358,1738
1.55844637,-0.3358,59
2.36595876,-0.3358,34
3.17347114,-0.3358,65
0.96758365,-0.3258,830
1.77509603,-0.3258,57
2.58260842,-0.3258,44
3.39012081,-0.3258,104
1.18423331,-0.3158,673
1.99174570,-0.3158,43
2.79925809,-0.3158,90
3.60677047,-0.3158,73
1.40088298,-0.3058,202
2.20839536,-0.3058,57
3.01590775,-0.3058,72
0.81002025,-0.2958,1124
1.61753264,-0.2958,63
2.42504503,-0.2958,35
3.23255742,-0.2958,73
1.02666992,-0.2858,781
1.83418231,-0.2858,55
2.64169469,-0.2858,55
3.44920708,-0.2858,101
1.24331958,-0.2758,573
2.05083197,-0.2758,34
2.85834436,-0.2758,89
3.66585675,-0.2758,64
1.45996925,-0.2658,74
2.26748164,-0.2658,52
3.07499402,-0.2658,86
0.86910653,-0.2558,984
1.67661891,-0.2558,57
2.48413130,-0.2558,55
3.29164369,-0.2558,83
1.08575619,-0.2458,728
1.89326858,-0.2458,44
2.70078097,-0.2458,56
3.50829335,-0.2458,104
1.30240586,-0.2358,412
2.10991824,-0.2358,40
2.91743063,-0.2358,91
0.71154313,-0.2258,2191
1.51905552,-0.2258,79
2.32656791,-0.2258,56
3.13408030,-0.2258,64
0.92819280,-0.2158,875
1.73570519,-0.2158,60
2.54321757,-0.2158,35
3.35072996,-0.2158,82
1.14484246,-0.2058,672
1.95235485,-0.2058,57
2.75986724,-0.2058,50
3.56737963,-0.2058,83
1.36149213,-0.1958,292
2.16900452,-0.1958,44
2.97651690,-0.1958,94
0.77062941,-0.1858,1502
1.57814179,-0.1858,56
2.38565418,-0.1858,53
3.19316657,-0.1858,55
0.98727907,-0.1758,775
1.79479146,-0.1758,50
2.60230385,-0.1758,43
3.40981623,-0.1758,106
1.20392874,-0.1658,667
2.01144112,-0.1658,41
2.81895351,-0.1658,84
3.62646590,-0.1658,62
1.42057840,-0.1558,180
2.22809079,-0.1558,39
3.03560318,-0.1558,71
0.82971568,-0.1458,1041
1.63722807,-0.1458,43
2.44474045,-0.1458,43
3.25225284,-0.1458,74
1.04636534,-0.1358,776
1.85387773,-0.1358,63
2.66139012,-0.1358,52
3.46890251,-0.1358,99
1.26301501,-0.1258,626
2.07052740,-0.1258,43
2.87803978,-0.1258,90
3.68555217,-0.1258,59
1.47966467,-0.1158,70
2.28717706,-0.1158,38
3.09468945,-0.1158,81
0.88880195,-0.1058,941
1.69631434,-0.1058,60
2.50382673,-0.1058,50
3.31133911,-0.1058,87
1.10545162,-0.0958,733
1.91296400,-0.0958,41
2.72047639,-0.0958,49
3.52798878,-0.0958,94
1.32210128,-0.0858,368
2.12961367,-0.0858,42
2.93712605,-0.0858,84
0.73123856,-0.0758,2140
1.53875095,-0.0758,69
2.34626333,-0.0758,40
3.15377572,-0.0758,58
0.94788822,-0.0658,872
1.75540061,-0.0658,50
2.56291300,-0.0658,33
3.37042538,-0.0658,76
1.16453789,-0.0558,723
1.97205028,-0.0558,50
2.77956266,-0.0558,75
3.58707505,-0.0558,81
1.38118755,-0.0458,259
2.18869994,-0.0458,50
2.99621233,-0.0458,91
0.79032483,-0.0358,1373
1.59783722,-0.0358,64
2.40534960,-0.0358,45
3.21286199,-0.0358,68
1.00697450,-0.0258,771
1.81448688,-0.0258,52
2.62199927,-0.0258,51
3.42951166,-0.0258,111
1.22362416,-0.0158,686
2.03113655,-0.0158,45
2.83864893,-0.0158,86
3.64616132,-0.0158,59
1.44027382,-0.0058,134
2.24778621,-0.0058,46
3.05529860,-0.0058,84
0.84941110,0.0042,1053
1.65692349,0.0042,64
2.46443588,0.0042,42
3.27194826,0.0042,72
1.06606077,0.0142,781
1.87357315,0.0142,29
2.68108554,0.0142,54
3.48859793,0.0142,96
1.28271043,0.0242,546
2.09022282,0.0242,39
2.89773521,0.0242,81
0.69184771,0.0342,2794
1.49936010,0.0342,62
2.30687248,0.0342,51
3.11438487,0.0342,66
0.90849737,0.0442,934
1.71600976,0.0442,50
2.52352215,0.0442,34
3.33103454,0.0442,83
1.12514704,0.0542,739
1.93265943,0.0542,41
2.74017181,0.0542,71
3.54768420,0.0542,84
1.34179670,0.0642,330
2.14930909,0.0642,54
2.95682148,0.0642,94
0.75093398,0.0742,1907
1.55844637,0.0742,62
2.36595876,0.0742,47
3.17347114,0.0742,68
0.96758365,0.0842,875
1.77509603,0.0842,43
2.58260842,0.0842,39
3.39012081,0.0842,102
1.18423331,0.0942,662
1.99174570,0.0942,36
2.79925809,0.0942,91
3.60677047,0.0942,77
1.40088298,0.1042,229
2.20839536,0.1042,51
3.01590775,0.1042,76
0.81002025,0.1142,1230
1.61753264,0.1142,68
2.42504503,0.1142,57
3.23255742,0.1142,56
1.02666992,0.1242,799
1.83418231,0.1242,59
2.64169469,0.1242,47
3.44920708,0.1242,85
1.24331958,0.1342,592
2.05083197,0.1342,39
2.85834436,0.1342,81
3.66585675,0.1342,77
1.45996925,0.1442,119
2.26748164,0.1442,36
3.07499402,0.1442,100
0.86910653,0.1542,1019
1.67661891,0.1542,60
2.48413130,0.1542,39
3.29164369,0.1542,83
1.08575619,0.1642,782
1.89326858,0.1642,62
2.70078097,0.1642,57
3.50829335,0.1642,101
1.30240586,0.1742,506
2.10991824,0.1742,43
2.91743063,0.1742,96
0.71154313,0.1842,2907
1.51905552,0.1842,68
2.32656791,0.1842,58
3.13408030,0.1842,51
0.92819280,0.1942,975
1.73570519,0.1942,59
2.54321757,0.1942,36
3.35072996,0.1942,97
1.14484246,0.2042,762
1.95235485,0.2042,54
2.75986724,0.2042,84
3.56737963,0.2042,79
1.36149213,0.2142,314
2.16900452,0.2142,56
2.97651690,0.2142,86
0.77062941,0.2242,1850
1.57814179,0.2242,68
2.38565418,0.2242,48
3.19316657,0.2242,67
0.98727907,0.2342,896
1.79479146,0.2342,53
2.60230385,0.2342,45
3.40981623,0.2342,97
1.20392874,0.2442,776
2.01144112,0.2442,58
2.81895351,0.2442,71
3.62646590,0.2442,57
1.42057840,0.2542,183
2.22809079,0.2542,55
3.03560318,0.2542,77
0.82971568,0.2642,1414
1.63722807,0.2642,94
2.44474045,0.2642,64
3.25225284,0.2642,65
1.04636534,0.2742,956
1.85387773,0.2742,55
2.66139012,0.2742,59
3.46890251,0.2742,96
1.26301501,0.2842,629
2.07052740,0.2842,47
2.87803978,0.2842,106
3.68555217,0.2842,52
1.47966467,0.2942,122
2.28717706,0.2942,60
3.09468945,0.2942,89
0.88880195,0.3042,1222
1.69631434,0.3042,73
2.50382673,0.3042,48
3.31133911,0.3042,89
1.10545162,0.3142,849
1.91296400,0.3142,58
2.72047639,0.3142,75
3.52798878,0.3142,85
1.32210128,0.3242,477
2.12961367,0.3242,63
2.93712605,0.3242,99
0.73123856,0.3342,3801
1.53875095,0.3342,110
2.34626333,0.3342,55
3.15377572,0.3342,63
0.94788822,0.3442,1176
1.75540061,0.3442,75
2.56291300,0.3442,43
3.37042538,0.3442,95
1.16453789,0.3542,858
1.97205028,0.3542,73
2.77956266,0.3542,96
3.58707505,0.3542,76
1.38118755,0.3642,332
2.18869994,0.3642,42
2.99621233,0.3642,88
0.79032483,0.3742,2328
1.59783722,0.3742,106
2.40534960,0.3742,51
3.21286199,0.3742,64
1.00697450,0.3842,1094
1.81448688,0.3842,75
2.62199927,0.3842,58
3.42951166,0.3842,102
1.22362416,0.3942,831
2.03113655,0.3942,73
2.83864893,0.3942,101
3.64616132,0.3942,68
1.44027382,0.4042,237
2.24778621,0.4042,73
3.05529860,0.4042,101
0.84941110,0.4142,1909
1.65692349,0.4142,119
2.46443588,0.4142,58
3.27194826,0.4142,82
1.06606077,0.4242,998
1.87357315,0.4242,89
2.68108554,0.4242,84
3.48859793,0.4242,88
1.28271043,0.4342,793
2.09022282,0.4342,59
2.89773521,0.4342,111
0.69184771,0.4442,1255576
1.49936010,0.4442,152
2.30687248,0.4442,67
3.11438487,0.4442,68
0.90849737,0.4542,1518
1.71600976,0.4542,121
2.52352215,0.4542,62
3.33103454,0.4542,76
1.12514704,0.4642,926
1.93265943,0.4642,78
2.74017181,0.4642,107
3.54768420,0.4642,100
1.34179670,0.4742,492
2.14930909,0.4742,71
2.95682148,0.4742,120
0.75093398,0.4842,1003750
1.55844637,0.4842,102
2.36595876,0.4842,92
3.17347114,0.4842,64
0.96758365,0.4942,1191
1.77509603,0.4942,91
2.58260842,0.4942,79
3.39012081,0.4942,76
1.18423331,0.5042,758
1.99174570,0.5042,81
2.79925809,0.5042,87
3.60677047,0.5042,82
1.40088298,0.5142,274
2.20839536,0.5142,104
3.01590775,0.5142,92
0.81002025,0.5242,118975
1.61753264,0.5242,86
2.42504503,0.5242,97
3.23255742,0.5242,79
1.02666992,0.5342,1028
1.83418231,0.5342,80
2.64169469,0.5342,88
3.44920708,0.5342,111
1.24331958,0.5442,689
2.05083197,0.5442,66
2.85834436,0.5442,101
3.66585675,0.5442,59
1.45996925,0.5542,134
2.26748164,0.5542,140
3.07499402,0.5542,68
0.86910653,0.5642,7791
1.67661891,0.5642,75
2.48413130,0.5642,85
3.29164369,0.5642,87
1.08575619,0.5742,973
1.89326858,0.5742,66
2.70078097,0.5742,83
3.50829335,0.5742,103
1.30240586,0.5842,524
2.10991824,0.5842,53
2.91743063,0.5842,105
0.71154313,0.5942,4715
1.51905552,0.5942,86
2.32656791,0.5942,152
3.13408030,0.5942,59
0.92819280,0.6042,3249
1.73570519,0.6042,81
2.54321757,0.6042,74
3.35072996,0.6042,97
1.14484246,0.6142,923
1.95235485,0.6142,64
2.75986724,0.6142,89
3.56737963,0.6142,94
1.36149213,0.6242,332
2.16900452,0.6242,90
2.97651690,0.6242,106
0.77062941,0.6342,2636
1.57814179,0.6342,74
2.38565418,0.6342,86
3.19316657,0.6342,70
0.98727907,0.6442,1714
1.79479146,0.6442,71
2.60230385,0.6442,64
3.40981623,0.6442,87
1.20392874,0.6542,883
2.01144112,0.6542,57
2.81895351,0.6542,107
3.62646590,0.6542,79
1.42057840,0.6642,215
2.22809079,0.6642,148
3.03560318,0.6642,87
0.82971568,0.6742,1646
1.63722807,0.6742,88
2.44474045,0.6742,57
3.25225284,0.6742,66
1.04636534,0.6842,1507
1.85387773,0.6842,54
2.66139012,0.6842,62
3.46890251,0.6842,101
1.26301501,0.6942,868
2.07052740,0.6942,59
2.87803978,0.6942,87
3.68555217,0.6942,71
1.47966467,0.7042,109
2.28717706,0.7042,146
3.09468945,0.7042,76
0.88880195,0.7142,1255
1.69631434,0.7142,83
2.50382673,0.7142,55
3.31133911,0.7142,83
1.10545162,0.7242,1007
1.91296400,0.7242,67
2.72047639,0.7242,69
3.52798878,0.7242,85
1.32210128,0.7342,820
2.12961367,0.7342,106
2.93712605,0.7342,101
0.73123856,0.7442,2463
1.53875095,0.7442,88
2.34626333,0.7442,104
3.15377572,0.7442,77
0.94788822,0.7542,1104
1.75540061,0.7542,69
2.56291300,0.7542,59
3.37042538,0.7542,99
1.16453789,0.7642,932
1.97205028,0.7642,38
2.77956266,0.7642,87
3.58707505,0.7642,75
1.38118755,0.7742,1785
2.18869994,0.7742,139
2.99621233,0.7742,102
0.79032483,0.7842,1510
1.59783722,0.7842,110
2.40534960,0.7842,65
3.21286199,0.7842,65
1.00697450,0.7942,1002
1.81448688,0.7942,75
2.62199927,0.7942,52
3.42951166,0.7942,106
1.22362416,0.8042,819
2.03113655,0.8042,58
2.83864893,0.8042,94
3.64616132,0.8042,85
1.44027382,0.8142,10537
2.24778621,0.8142,172
3.05529860,0.8142,83
0.84941110,0.8242,1094
1.65692349,0.8242,70
2.46443588,0.8242,64
3.27194826,0.8242,76
1.06606077,0.8342,875
1.87357315,0.8342,46
2.68108554,0.8342,83
3.48859793,0.8342,90
1.28271043,0.8442,689
2.09022282,0.8442,87
2.89773521,0.8442,96
0.69184771,0.8542,2625
1.49936010,0.8542,15692
2.30687248,0.8542,121
3.11438487,0.8542,67
0.90849737,0.8642,1005
1.71600976,0.8642,91
2.52352215,0.8642,55
3.33103454,0.8642,89
1.12514704,0.8742,795
1.93265943,0.8742,70
2.74017181,0.8742,79
3.54768420,0.8742,102
1.34179670,0.8842,407
2.14930909,0.8842,146
2.95682148,0.8842,105
0.75093398,0.8942,1846
1.55844637,0.8942,8780
2.36595876,0.8942,74
3.17347114,0.8942,69
0.96758365,0.9042,901
1.77509603,0.9042,81
2.58260842,0.9042,50
3.39012081,0.9042,80
1.18423331,0.9142,697
1.99174570,0.9142,60
2.79925809,0.9142,112
3.60677047,0.9142,77
1.40088298,0.9242,269
2.20839536,0.9242,188
3.01590775,0.9242,78
0.81002025,0.9342,1128
1.61753264,0.9342,548
2.42504503,0.9342,56
3.23255742,0.9342,79
1.02666992,0.9442,891
1.83418231,0.9442,78
2.64169469,0.9442,69
3.44920708,0.9442,104
1.24331958,0.9542,658
2.05083197,0.9542,69
2.85834436,0.9542,114
3.66585675,0.9542,76
1.45996925,0.9642,146
2.26748164,0.9642,157
3.07499402,0.9642,74
0.86910653,0.9742,1002
1.67661891,0.9742,202
2.48413130,0.9742,54
3.29164369,0.9742,81
1.08575619,0.9842,763
1.89326858,0.9842,60
2.70078097,0.9842,66
3.50829335,0.9842,108
1.30240586,0.9942,593
2.10991824,0.9942,100
2.91743063,0.9942,93
0.71154313,1.0042,2221
1.51905552,1.0042,95
2.32656791,1.0042,118
3.13408030,1.0042,61
0.92819280,1.0142,892
1.73570519,1.0142,153
2.54321757,1.0142,67
3.35072996,1.0142,98
1.14484246,1.0242,742
1.95235485,1.0242,68
2.75986724,1.0242,100
3.56737963,1.0242,99
1.36149213,1.0342,329
2.16900452,1.0342,140
2.97651690,1.0342,110
0.77062941,1.0442,1615
1.57814179,1.0442,100
2.38565418,1.0442,57
3.19316657,1.0442,76
0.98727907,1.0542,730
1.79479146,1.0542,105
2.60230385,1.0542,62
3.40981623,1.0542,114
1.20392874,1.0642,715
2.01144112,1.0642,81
2.81895351,1.0642,89
3.62646590,1.0642,77
1.42057840,1.0742,205
2.22809079,1.0742,214
3.03560318,1.0742,83
0.82971568,1.0842,1003
1.63722807,1.0842,77
2.44474045,1.0842,77
3.25225284,1.0842,87
1.04636534,1.0942,731
1.85387773,1.0942,78
2.66139012,1.0942,69
3.46890251,1.0942,105
1.26301501,1.1042,643
2.07052740,1.1042,192
2.87803978,1.1042,114
3.68555217,1.1042,56
1.47966467,1.1142,91
2.28717706,1.1142,189
3.09468945,1.1142,89
0.88880195,1.1242,907
1.69631434,1.1242,74
2.50382673,1.1242,59
3.31133911,1.1242,80
1.10545162,1.1342,704
1.91296400,1.1342,60
2.72047639,1.1342,75
3.52798878,1.1342,87
1.32210128,1.1442,437
2.12961367,1.1442,1658
2.93712605,1.1442,120
0.73123856,1.1542,2051
1.53875095,1.1542,97
2.34626333,1.1542,115
3.15377572,1.1542,70
0.94788822,1.1642,851
1.75540061,1.1642,62
2.56291300,1.1642,51
3.37042538,1.1642,103
1.16453789,1.1742,707
1.97205028,1.1742,75
2.77956266,1.1742,83
3.58707505,1.1742,83
1.38118755,1.1842,270
2.18869994,1.1842,32570
2.99621233,1.1842,94
0.79032483,1.1942,1196
1.59783722,1.1942,91
2.40534960,1.1942,81
3.21286199,1.1942,67
1.00697450,1.2042,742
1.81448688,1.2042,58
2.62199927,1.2042,78
3.42951166,1.2042,110
1.22362416,1.2142,588
2.03113655,1.2142,110
2.83864893,1.2142,120
3.64616132,1.2142,63
1.44027382,1.2242,190
2.24778621,1.2242,91178
3.05529860,1.2242,100
0.84941110,1.2342,922
1.65692349,1.2342,87
2.46443588,1.2342,66
3.27194826,1.2342,99
1.06606077,1.2442,693
1.87357315,1.2442,60
2.68108554,1.2442,82
3.48859793,1.2442,106
1.28271043,1.2542,574
2.09022282,1.2542,127
2.89773521,1.2542,101
0.69184771,1.2642,2363
1.49936010,1.2642,102
2.30687248,1.2642,26896
3.11438487,1.2642,77
0.90849737,1.2742,845
1.71600976,1.2742,60
2.52352215,1.2742,69
3.33103454,1.2742,84
1.12514704,1.2842,666
1.93265943,1.2842,53
2.74017181,1.2842,89
3.54768420,1.2842,78
1.34179670,1.2942,363
2.14930909,1.2942,207
2.95682148,1.2942,88
0.75093398,1.3042,1700
1.55844637,1.3042,98
2.36595876,1.3042,1063
3.17347114,1.3042,64
0.96758365,1.3142,809
1.77509603,1.3142,69
2.58260842,1.3142,66
3.39012081,1.3142,102
1.18423331,1.3242,660
1.99174570,1.3242,63
2.79925809,1.3242,99
3.60677047,1.3242,79
1.40088298,1.3342,228
2.20839536,1.3342,266
3.01590775,1.3342,104
0.81002025,1.3442,1025
1.61753264,1.3442,79
2.42504503,1.3442,424
3.23255742,1.3442,72
1.02666992,1.3542,738
1.83418231,1.3542,80
2.64169469,1.3542,78
3.44920708,1.3542,102
1.24331958,1.3642,588
2.05083197,1.3642,84
2.85834436,1.3642,99
3.66585675,1.3642,66
1.45996925,1.3742,121
2.26748164,1.3742,206
3.07499402,1.3742,77
0.86910653,1.3842,890
1.67661891,1.3842,81
2.48413130,1.3842,182
3.29164369,1.3842,83
1.08575619,1.3942,685
1.89326858,1.3942,56
2.70078097,1.3942,84
3.50829335,1.3942,102
1.30240586,1.4042,478
2.10991824,1.4042,144
2.91743063,1.4042,86
0.71154313,1.4142,2159
1.51905552,1.4142,72
2.32656791,1.4142,99
3.13408030,1.4142,78
0.92819280,1.4242,773
1.73570519,1.4242,78
2.54321757,1.4242,86
3.35072996,1.4242,95
1.14484246,1.4342,593
1.95235485,1.4342,66
2.75986724,1.4342,96
3.56737963,1.4342,94
1.36149213,1.4442,285
2.16900452,1.4442,216
2.97651690,1.4442,96
0.77062941,1.4542,1411
1.57814179,1.4542,88
2.38565418,1.4542,86
3.19316657,1.4542,77
0.98727907,1.4642,738
1.79479146,1.4642,66
2.60230385,1.4642,98
3.40981623,1.4642,93
1.20392874,1.4742,585
2.01144112,1.4742,63
2.81895351,1.4742,102
3.62646590,1.4742,79
1.42057840,1.4842,167
2.22809079,1.4842,259
3.03560318,1.4842,87
0.82971568,1.4942,918
1.63722807,1.4942,76
2.44474045,1.4942,75
3.25225284,1.4942,65
1.04636534,1.5042,687
1.85387773,1.5042,50
2.66139012,1.5042,62
3.46890251,1.5042,104
1.26301501,1.5142,538
2.07052740,1.5142,75
2.87803978,1.5142,124
3.68555217,1.5142,76
1.47966467,1.5242,69
2.28717706,1.5242,202
3.09468945,1.5242,66
0.88880195,1.5342,887
1.69631434,1.5342,76
2.50382673,1.5342,65
3.31133911,1.5342,88
1.10545162,1.5442,670
1.91296400,1.5442,51
2.72047639,1.5442,75
3.52798878,1.5442,87
1.32210128,1.5542,421
2.12961367,1.5542,98
2.93712605,1.5542,180
0.73123856,1.5642,1860
1.53875095,1.5642,63
2.34626333,1.5642,65
3.15377572,1.5642,70
0.94788822,1.5742,726
1.75540061,1.5742,74
2.56291300,1.5742,53
3.37042538,1.5742,94
1.16453789,1.5842,572
1.97205028,1.5842,60
2.77956266,1.5842,92
3.58707505,1.5842,77
1.38118755,1.5942,275
2.18869994,1.5942,175
2.99621233,1.5942,718
0.79032483,1.6042,1238
1.59783722,1.6042,76
2.40534960,1.6042,67
3.21286199,1.6042,82
1.00697450,1.6142,738
1.81448688,1.6142,63
2.62199927,1.6142,54
3.42951166,1.6142,101
1.22362416,1.6242,494
2.03113655,1.6242,60
2.83864893,1.6242,107
3.64616132,1.6242,75
1.44027382,1.6342,120
2.24778621,1.6342,180
3.05529860,1.6342,1012
0.84941110,1.6442,939
1.65692349,1.6442,62
2.46443588,1.6442,69
3.27194826,1.6442,75
1.06606077,1.6542,679
1.87357315,1.6542,63
2.68108554,1.6542,56
3.48859793,1.6542,102
1.28271043,1.6642,494
2.09022282,1.6642,64
2.89773521,1.6642,103
0.69184771,1.6742,2256
1.49936010,1.6742,56
2.30687248,1.6742,113
3.11438487,1.6742,194
0.90849737,1.6842,770
1.71600976,1.6842,57
2.52352215,1.6842,62
3.33103454,1.6842,81
1.12514704,1.6942,622
1.93265943,1.6942,69
2.74017181,1.6942,90
3.54768420,1.6942,110
1.34179670,1.7042,311
2.14930909,1.7042,85
2.95682148,1.7042,92
0.75093398,1.7142,1650
1.55844637,1.7142,47
2.36595876,1.7142,77
3.17347114,1.7142,84
0.96758365,1.7242,790
1.77509603,1.7242,42
2.58260842,1.7242,50
3.39012081,1.7242,93
1.18423331,1.7342,591
1.99174570,1.7342,52
2.79925809,1.7342,79
3.60677047,1.7342,76
1.40088298,1.7442,203
2.20839536,1.7442,137
3.01590775,1.7442,84
0.81002025,1.7542,987
1.61753264,1.7542,56
2.42504503,1.7542,66
3.23255742,1.7542,81
1.02666992,1.7642,710
1.83418231,1.7642,48
2.64169469,1.7642,53
3.44920708,1.7642,88
1.24331958,1.7742,555
2.05083197,1.7742,62
2.85834436,1.7742,112
3.66585675,1.7742,74
1.45996925,1.7842,80
2.26748164,1.7842,159
3.07499402,1.7842,95
0.86910653,1.7942,865
1.67661891,1.7942,48
2.48413130,1.7942,57
3.29164369,1.7942,88
1.08575619,1.8042,622
1.89326858,1.8042,68
2.70078097,1.8042,55
3.50829335,1.8042,115
1.30240586,1.8142,485
2.10991824,1.8142,61
2.91743063,1.8142,104
0.71154313,1.8242,2017
1.51905552,1.8242,55
2.32656791,1.8242,108
3.13408030,1.8242,70
0.92819280,1.8342,799
1.73570519,1.8342,50
2.54321757,1.8342,37
3.35072996,1.8342,85
1.14484246,1.8442,608
1.95235485,1.8442,52
2.75986724,1.8442,79
3.56737963,1.8442,100
1.36149213,1.8542,300
2.16900452,1.8542,83
2.97651690,1.8542,89
0.77062941,1.8642,1314
1.57814179,1.8642,55
2.38565418,1.8642,76
3.19316657,1.8642,84
0.98727907,1.8742,690
1.79479146,1.8742,56
2.60230385,1.8742,51
3.40981623,1.8742,104
1.20392874,1.8842,580
2.01144112,1.8842,64
2.81895351,1.8842,98
3.62646590,1.8842,80
1.42057840,1.8942,183
2.22809079,1.8942,108
3.03560318,1.8942,94
0.82971568,1.9042,871
1.63722807,1.9042,56
2.44474045,1.9042,50
3.25225284,1.9042,60
1.04636534,1.9142,689
1.85387773,1.9142,49
2.66139012,1.9142,59
3.46890251,1.9142,91
1.26301501,1.9242,506
2.07052740,1.9242,42
2.87803978,1.9242,91
3.68555217,1.9242,106
1.47966467,1.9342,68
2.28717706,1.9342,130
3.09468945,1.9342,74
0.88880195,1.9442,819
1.69631434,1.9442,44
2.50382673,1.9442,59
3.31133911,1.9442,89
1.10545162,1.9542,615
1.91296400,1.9542,43
2.72047639,1.9542,62
3.52798878,1.9542,95
1.32210128,1.9642,389
2.12961367,1.9642,58
2.93712605,1.9642,106
0.73123856,1.9742,1871
1.53875095,1.9742,51
2.34626333,1.9742,100
3.15377572,1.9742,80
0.94788822,1.9842,674
1.75540061,1.9842,47
2.56291300,1.9842,52
3.37042538,1.9842,90
1.16453789,1.9942,601
1.97205028,1.9942,33
2.77956266,1.9942,70
3.58707505,1.9942,103
1.38118755,2.0042,244
2.18869994,2.0042,47
2.99621233,2.0042,81
0.79032483,2.0142,1108
1.59783722,2.0142,47
2.40534960,2.0142,69
3.21286199,2.0142,60
1.00697450,2.0242,652
1.81448688,2.0242,53
2.62199927,2.0242,51
3.42951166,2.0242,96
1.22362416,2.0342,507
2.03113655,2.0342,36
2.83864893,2.0342,108
3.64616132,2.0342,87
1.44027382,2.0442,108
2.24778621,2.0442,57
3.05529860,2.0442,87
0.84941110,2.0542,824
1.65692349,2.0542,39
2.46443588,2.0542,63
3.27194826,2.0542,77
1.06606077,2.0642,614
1.87357315,2.0642,48
2.68108554,2.0642,56
3.48859793,2.0642,98
1.28271043,2.0742,483
2.09022282,2.0742,38
2.89773521,2.0742,103
0.69184771,2.0842,2094
1.49936010,2.0842,53
2.30687248,2.0842,43
3.11438487,2.0842,57
0.90849737,2.0942,792
1.71600976,2.0942,44
2.52352215,2.0942,58
3.33103454,2.0942,86
1.12514704,2.1042,590
1.93265943,2.1042,47
2.74017181,2.1042,91
3.54768420,2.1042,98
1.34179670,2.1142,332
2.14930909,2.1142,44
2.95682148,2.1142,86
0.75093398,2.1242,1513
1.55844637,2.1242,52
2.36595876,2.1242,50
3.17347114,2.1242,81
0.96758365,2.1342,682
1.77509603,2.1342,40
2.58260842,2.1342,57
3.39012081,2.1342,93
1.18423331,2.1442,551
1.99174570,2.1442,43
2.79925809,2.1442,68
3.60677047,2.1442,72
1.40088298,2.1542,181
2.20839536,2.1542,51
3.01590775,2.1542,85
0.81002025,2.1642,912
1.61753264,2.1642,48
2.42504503,2.1642,73
3.23255742,2.1642,82
1.02666992,2.1742,673
1.83418231,2.1742,40
2.64169469,2.1742,59
3.44920708,2.1742,104
1.24331958,2.1842,546
2.05083197,2.1842,32
2.85834436,2.1842,100
3.66585675,2.1842,69
1.45996925,2.1942,77
2.26748164,2.1942,48
3.07499402,2.1942,85
0.86910653,2.2042,829
1.67661891,2.2042,50
2.48413130,2.2042,79
3.29164369,2.2042,80
1.08575619,2.2142,565
1.89326858,2.2142,44
2.70078097,2.2142,58
3.50829335,2.2142,108
1.30240586,2.2242,423
2.10991824,2.2242,41
2.91743063,2.2242,81
0.71154313,2.2342,1966
1.51905552,2.2342,59
2.32656791,2.2342,58
3.13408030,2.2342,67
0.92819280,2.2442,676
1.73570519,2.2442,56
2.54321757,2.2442,68
3.35072996,2.2442,108
1.14484246,2.2542,575
1.95235485,2.2542,42
2.75986724,2.2542,77
3.56737963,2.2542,91
1.36149213,2.2642,303
2.16900452,2.2642,46
2.97651690,2.2642,92
0.77062941,2.2742,1338
1.57814179,2.2742,59
2.38565418,2.2742,45
3.19316657,2.2742,63
0.98727907,2.2842,678
1.79479146,2.2842,50
2.60230385,2.2842,66
3.40981623,2.2842,102
1.20392874,2.2942,518
2.01144112,2.2942,44
2.81895351,2.2942,96
3.62646590,2.2942,84
1.42057840,2.3042,174
2.22809079,2.3042,47
3.03560318,2.3042,90
0.82971568,2.3142,809
1.63722807,2.3142,66
2.44474045,2.3142,39
3.25225284,2.3142,70
1.04636534,2.3242,591
1.85387773,2.3242,42
2.66139012,2.3242,65
3.46890251,2.3242,103
1.26301501,2.3342,500
2.07052740,2.3342,41
2.87803978,2.3342,114
3.68555217,2.3342,62
1.47966467,2.3442,60
2.28717706,2.3442,34
3.09468945,2.3442,73
0.88880195,2.3542,729
1.69631434,2.3542,42
2.50382673,2.3542,46
3.31133911,2.3542,81
1.10545162,2.3642,565
1.91296400,2.3642,32
2.72047639,2.3642,74
3.52798878,2.3642,96
1.32210128,2.3742,391
2.12961367,2.3742,38
2.93712605,2.3742,97
0.73123856,2.3842,1670
1.53875095,2.3842,56
2.34626333,2.3842,38
3.15377572,2.3842,66
0.94788822,2.3942,630
1.75540061,2.3942,38
2.56291300,2.3942,52
3.37042538,2.3942,90
1.16453789,2.4042,425
1.97205028,2.4042,26
2.77956266,2.4042,72
3.58707505,2.4042,86
1.38118755,2.4142,257
2.18869994,2.4142,42
2.99621233,2.4142,77
0.79032483,2.4242,922
1.59783722,2.4242,53
2.40534960,2.4242,38
3.21286199,2.4242,76
1.00697450,2.4342,569
1.81448688,2.4342,34
2.62199927,2.4342,59
3.42951166,2.4342,102
1.22362416,2.4442,405
2.03113655,2.4442,47
2.83864893,2.4442,97
3.64616132,2.4442,76
1.44027382,2.4542,132
2.24778621,2.4542,35
3.05529860,2.4542,63
0.84941110,2.4642,648
1.65692349,2.4642,47
2.46443588,2.4642,33
3.27194826,2.4642,71
1.06606077,2.4742,473
1.87357315,2.4742,35
2.68108554,2.4742,52
3.48859793,2.4742,94
1.28271043,2.4842,341
2.09022282,2.4842,39
2.89773521,2.4842,99
0.69184771,2.4942,1648
1.49936010,2.4942,58
2.30687248,2.4942,45
3.11438487,2.4942,72
0.90849737,2.5042,520
1.71600976,2.5042,53
2.52352215,2.5042,28
3.33103454,2.5042,65
1.12514704,2.5142,392
1.93265943,2.5142,48
2.74017181,2.5142,70
3.54768420,2.5142,104
1.34179670,2.5242,314
2.14930909,2.5242,31
2.95682148,2.5242,104
0.75093398,2.5342,1223
1.55844637,2.5342,38
2.36595876,2.5342,37
3.17347114,2.5342,53
0.96758365,2.5442,424
1.77509603,2.5442,39
2.58260842,2.5442,36
3.39012081,2.5442,94
1.18423331,2.5542,360
1.99174570,2.5542,33
2.79925809,2.5542,92
3.60677047,2.5542,94
1.40088298,2.5642,204
2.20839536,2.5642,50
3.01590775,2.5642,78
0.81002025,2.5742,598
1.61753264,2.5742,38
2.42504503,2.5742,28
3.23255742,2.5742,67
1.02666992,2.5842,379
1.83418231,2.5842,38
2.64169469,2.5842,28
3.44920708,2.5842,87
1.24331958,2.5942,313
2.05083197,2.5942,35
2.85834436,2.5942,115
3.66585675,2.5942,76
1.45996925,2.6042,68
2.26748164,2.6042,36
3.07499402,2.6042,71
0.86910653,2.6142,506
1.67661891,2.6142,54
2.48413130,2.6142,38
3.29164369,2.6142,64
1.08575619,2.6242,309
1.89326858,2.6242,23
2.70078097,2.6242,57
3.50829335,2.6242,97
1.30240586,2.6342,270
2.10991824,2.6342,28
2.91743063,2.6342,110
0.71154313,2.6442,1385
1.51905552,2.6442,34
2.32656791,2.6442,26
3.13408030,2.6442,63
0.92819280,2.6542,414
1.73570519,2.6542,33
2.54321757,2.6542,26
3.35072996,2.6542,77
1.14484246,2.6642,313
1.95235485,2.6642,27
2.75986724,2.6642,79
3.56737963,2.6642,95
1.36149213,2.6742,243
2.16900452,2.6742,35
2.97651690,2.6742,74
0.77062941,2.6842,881
1.57814179,2.6842,47
2.38565418,2.6842,28
3.19316657,2.6842,73
0.98727907,2.6942,316
1.79479146,2.6942,35
2.60230385,2.6942,27
3.40981623,2.6942,94
1.20392874,2.7042,296
2.01144112,2.7042,20
2.81895351,2.7042,71
3.62646590,2.7042,71
1.42057840,2.7142,177
2.22809079,2.7142,43
3.03560318,2.7142,78
0.82971568,2.7242,480
1.63722807,2.7242,30
2.44474045,2.7242,26
3.25225284,2.7242,56
1.04636534,2.7342,302
1.85387773,2.7342,33
2.66139012,2.7342,47
3.46890251,2.7342,106
1.26301501,2.7442,262
2.07052740,2.7442,27
2.87803978,2.7442,82
3.68555217,2.7442,59
1.47966467,2.7542,37
2.28717706,2.7542,34
3.09468945,2.7542,70
0.88880195,2.7642,310
1.69631434,2.7642,31
2.50382673,2.7642,28
3.31133911,2.7642,77
1.10545162,2.7742,266
1.91296400,2.7742,31
2.72047639,2.7742,45
3.52798878,2.7742,120
1.32210128,2.7842,200
2.12961367,2.7842,28
2.93712605,2.7842,91
0.73123856,2.7942,986
1.53875095,2.7942,39
2.34626333,2.7942,22
3.15377572,2.7942,58
0.94788822,2.8042,301
1.75540061,2.8042,34
2.56291300,2.8042,27
3.37042538,2.8042,83
1.16453789,2.8142,203
1.97205028,2.8142,21
2.77956266,2.8142,55
3.58707505,2.8142,72
1.38118755,2.8242,199
2.18869994,2.8242,38
2.99621233,2.8242,79
0.79032483,2.8342,553
1.59783722,2.8342,23
2.40534960,2.8342,30
3.21286199,2.8342,67
1.00697450,2.8442,267
1.81448688,2.8442,24
2.62199927,2.8442,31
3.42951166,2.8442,94
1.22362416,2.8542,187
2.03113655,2.8542,28
2.83864893,2.8542,66
3.64616132,2.8542,79
1.44027382,2.8642,94
2.24778621,2.8642,26
3.05529860,2.8642,81
0.84941110,2.8742,287
1.65692349,2.8742,34
2.46443588,2.8742,24
3.27194826,2.8742,74
1.06606077,2.8842,185
1.87357315,2.8842,26
2.68108554,2.8842,49
3.48859793,2.8842,77
1.28271043,2.8942,172
2.09022282,2.8942,37
2.89773521,2.8942,86
0.69184771,2.9042,696
1.49936010,2.9042,25
2.30687248,2.9042,27
3.11438487,2.9042,61
0.90849737,2.9142,232
1.71600976,2.9142,41
2.52352215,2.9142,23
3.33103454,2.9142,77
1.12514704,2.9242,176
1.93265943,2.9242,27
2.74017181,2.9242,49
3.54768420,2.9242,70
1.34179670,2.9342,136
2.14930909,2.9342,29
2.95682148,2.9342,86
0.75093398,2.9442,768
1.55844637,2.9442,39
2.36595876,2.9442,14
3.17347114,2.9442,63
0.96758365,2.9542,211
1.77509603,2.9542,31
2.58260842,2.9542,23
3.39012081,2.9542,103
1.18423331,2.9642,134
1.99174570,2.9642,26
2.79925809,2.9642,54
3.60677047,2.9642,78
1.40088298,2.9742,115
2.20839536,2.9742,28
3.01590775,2.9742,69
0.81002025,2.9842,265
1.61753264,2.9842,24
2.42504503,2.9842,18
3.23255742,2.9842,52
1.02666992,2.9942,150
1.83418231,2.9942,27
2.64169469,2.9942,27
3.44920708,2.9942,83
1.24331958,3.0042,118
2.05083197,3.0042,22
2.85834436,3.0042,87
3.66585675,3.0042,62
1.45996925,3.0142,54
2.26748164,3.0142,23
3.07499402,3.0142,52
0.86910653,3.0242,161
1.67661891,3.0242,33
2.48413130,3.0242,24
3.29164369,3.0242,73
1.08575619,3.0342,151
1.89326858,3.0342,32
2.70078097,3.0342,39
3.50829335,3.0342,61
1.30240586,3.0442,100
2.10991824,3.0442,27
2.91743063,3.0442,93
0.71154313,3.0542,300
1.51905552,3.0542,23
2.32656791,3.0542,27
3.13408030,3.0542,55
0.92819280,3.0642,139
1.73570519,3.0642,28
2.54321757,3.0642,15
3.35072996,3.0642,78
1.14484246,3.0742,100
1.95235485,3.0742,29
2.75986724,3.0742,66
3.56737963,3.0742,81
1.36149213,3.0842,73
2.16900452,3.0842,20
2.97651690,3.0842,84
0.77062941,3.0942,305
1.57814179,3.0942,26
2.38565418,3.0942,24
3.19316657,3.0942,49
0.98727907,3.1042,109
1.79479146,3.1042,24
2.60230385,3.1042,26
3.40981623,3.1042,77
1.20392874,3.1142,76
2.01144112,3.1142,25
2.81895351,3.1142,57
3.62646590,3.1142,61
1.42057840,3.1242,68
2.22809079,3.1242,35
3.03560318,3.1242,60
0.82971568,3.1342,126
1.63722807,3.1342,29
2.44474045,3.1342,14
3.25225284,3.1342,54
1.04636534,3.1442,78
1.85387773,3.1442,25
2.66139012,3.1442,31
3.46890251,3.1442,93
1.26301501,3.1542,58
2.07052740,3.1542,29
2.87803978,3.1542,67
3.68555217,3.1542,45
1.47966467,3.1642,37
2.28717706,3.1642,37
3.09468945,3.1642,37
0.88880195,3.1742,63
1.69631434,3.1742,22
2.50382673,3.1742,15
3.31133911,3.1742,66
1.10545162,3.1842,50
1.91296400,3.1842,21
2.72047639,3.1842,35
3.52798878,3.1842,62
1.32210128,3.1942,41
2.12961367,3.1942,25
2.93712605,3.1942,68
0.73123856,3.2042,91
1.53875095,3.2042,28
2.34626333,3.2042,28
3.15377572,3.2042,40
0.94788822,3.2142,42
1.75540061,3.2142,14
2.56291300,3.2142,18
3.37042538,3.2142,74
3.68555217,3.2142,44